Workbook

Sheet Cover
B4: DEVELOPMENT FEASIBILITY & APPRAISAL REVIEW
B7: 917 South Andrews Avenue | Fort Lauderdale, FL 33316
B9: Institutional Underwriting Workbook & Investment Committee Package
B13: Prepared for | C13: Investment Committee / Capital Partners
B14: Subject | C14: Agora Mediterranean Market site — Mixed-Use Redevelopment
B15: Land Area | C15: 38,207 SF (0.88 acres)
B16: Zoning | C16: RAC-RPO (Regional Activity Center — Residential Permitted Overlay)
B17: Appraised Value (As-Is) | C17: $11,100,000 ($290.00 / land SF)
B18: Appraisal Date | C18: September 25, 2025 (Value date: September 18, 2025)
B19: Central Question | C19: Can a rational developer pay $11.1M for this land and still hit acceptable risk-adjusted returns?
B23: TAB INDEX
B24: 01 Assumptions | C24: Centralized inputs, scenario toggle (Conservative / Base / Aggressive)
B25: 02 Source Document Register | C25: Appraisal & survey inputs, dates, preparers, references
B26: 03 Evidence Map | C26: Every major assumption traced to its source document
B27: 04 Feasibility Dashboard | C27: One-page executive summary + PROCEED / CAUTION verdict
B28: 05 Residual Land Value | C28: Cost-stack residual + developer-supported value
B29: 06 Land Value Reality Check | C29: Appraisal vs developer-supported, variance
B30: 07 Negotiation Waterfall | C30: $11.1M bridged down to supported value
B31: 08 Residual Value Curve | C31: Residual land value vs developer profit hurdle
B32: 09 Rate Destruction Map | C32: Interest rate x construction cost heat map
B33: 10 Buildable Area | C33: FAR 4.0 / 6.0 / 8.0 program comparison
B34: 11 Site Constraint Scorecard | C34: Flood / HVHZ / entitlement / insurance / financing risk
B35: 12 Tornado Sensitivity | C35: Variables ranked by impact on residual value
... B37: 14 IC Tear Sheet | C37: One-page committee conclusion
B39: Methodology note: This workbook is a neutral feasibility tool. The recommendation and supported land value are driven entirely by the assumptions on the Assumptions tab and recalculate when those inputs change. No conclusion is hardcoded. Figures sourced outside the appraisal/survey are flagged as Analyst Assumptions (yellow) on the Evidence Map.

Sheet IC Tear Sheet
B1: INVESTMENT COMMITTEE TEAR SHEET
B2: 917 S Andrews Avenue, Fort Lauderdale, FL 33316 | Development Feasibility & Appraisal Review
B3: =CONCATENATE("Active scenario: ",Assumptions!C4," | Appraised value under review: $11,100,000 ($290.00/land SF) | Land: 38,207 SF / 0.88 ac | Zoning: RAC-RPO") -> Active scenario: Base | Appraised value under review: $11,100,000 ($290.00/land SF) | Land: 38,207 SF / 0.88 ac | Zoning: RAC-RPO
B5: EXECUTIVE SUMMARY
B6: This review tests whether the $11.1M appraised value is supported by forward-looking development economics rather than backward-looking comparable sales. A residual land value is derived from a stabilized multifamily program (RAC-RPO, FAR 6) net of hard/soft costs, HVHZ and flood premiums, demolition, construction financing (average-outstanding-balance method), and a required developer profit. The supported land value is the residual the project can pay while still clearing the profit hurdle — compared directly against the appraisal.
B10: DEVELOPER FEASIBILITY GAUGE | F10: KEY OUTPUTS
B11: ='Residual Land Value'!C45 -> CAUTION — NEGOTIATE | F11: Supported land value | H11: ='Residual Land Value'!C36 -> 8957792.5
F12: Supported $/land SF | H12: ='Residual Land Value'!C37 -> 234.45422
F13: Appraised value | H13: =a_appr -> 11100000
B14: =CONCATENATE("Coverage ratio (supported / appraised): ",TEXT('Residual Land Value'!C44,"0.0%")) -> Coverage ratio (supported / appraised): 80.7% | F14: Variance to appraisal | H14: ='Residual Land Value'!C41 -> -2142207.5
F15: Variance % | H15: ='Residual Land Value'!C42 -> -0.19299167
F16: Stabilized value | H16: ='Residual Land Value'!C32 -> 1.2058819e+08
B17: NEGOTIATION WATERFALL — APPRAISAL TO SUPPORTED VALUE
F18: Profit required | H18: ='Residual Land Value'!C35 -> 16625803
B29: RESIDUAL LAND VALUE vs DEVELOPER PROFIT HURDLE
B42: RISK SUMMARY
B43: Flood (AE zone): High | D43: HVHZ construction: High | F43: Insurance cost: High
B44: Financing env.: High | D44: Entitlement FAR 6: Medium | F44: Parking burden: Medium
B45: Absorption / lease-up: Medium • Overall risk profile: ELEVATED — multiple high-rated cost & financing constraints compress residual value.
B47: RECOMMENDATION
B48: =IF('Residual Land Value'!C44>=1,"The appraisal value of $11.1M is supported by current development economics under the active scenario. A rational developer can acquire the site at the appraised value and still clear the required profit hurdle.",IF('Residual Land Value'!C44>=0.75,"The appraisal value of $11.1M is not fully supported by current development economics under base-case financing and construction assumptions. Supported land value falls below the appraisal; the gap is bridgeable through price negotiation, entitlement upside, or improved financing terms.","The appraisal value of $11.1M is not supported by current development economics. At the modeled profit hurdle the site cannot carry the appraised price; a materially lower basis is required to underwrite a viable project.")) -> The appraisal value of $11.1M is not fully supported by current development economics under base-case financing and construction assumptions. Supported land value falls below the appraisal; the gap is bridgeable through price negotiation, entitlement upside, or improved financing terms.
B52: Prepared as an institutional development feasibility review. Figures are model projections under stated assumptions, not guaranteed returns. Analyst Assumptions flagged in source tabs. Not an appraisal or investment advice.

Sheet Feasibility Dashboard
A1: DEVELOPER FEASIBILITY DASHBOARD
A2: 917 S Andrews Ave — live outputs from Assumptions scenario toggle. Verdict is model-driven, not predetermined.
B4: ACTIVE SCENARIO: | C4: =Assumptions!C4 -> Base
B6: PROPERTY | E6: LOCATION | H6: KEY METRICS
B7: [ Property Photo Placeholder ] 917 S Andrews Ave Fort Lauderdale, FL 33316 | E7: [ Map Placeholder ] RAC-RPO — Regional Activity Center Frontage: S Andrews Ave / SW 9th St / SW 10th St Flood Zone: AE | H7: Land size (SF) | I7: =a_landSF -> 38207
H8: Appraised value | I8: =a_appr -> 11100000
H9: Appraised $/SF | I9: =a_appr/a_landSF -> 290.52268
H10: FAR scenario | I10: =a_far -> 6
H11: Buildable SF (gross) | I11: =r_gba -> 229242
H12: Residential units | I12: =r_units -> 246
B13: DEVELOPER-SUPPORTED LAND VALUE | H13: RECOMMENDATION
B14: =r_resid -> 8957792.5 | H14: ='Residual Land Value'!C45 -> CAUTION — NEGOTIATE
H17: Supported / appraised | I17: =r_cover -> 0.80700833
B18: Appraised | C18: =a_appr -> 11100000 | E18: Supported | F18: =r_resid -> 8957792.5 | H18: Variance | I18: =r_resid-a_appr -> -2142207.5
B20: Read: when supported value < appraised value, the appraisal is not fully supported by current development economics under the selected scenario; the gap is the basis for price negotiation. Toggle the scenario on the Assumptions tab to stress the conclusion.

Sheet Assumptions
A1: ASSUMPTIONS / CONTROL PANEL
A2: All model inputs live here. Blue = hardcoded input. Scenario toggle drives the active column via INDEX/MATCH. No conclusion is hardcoded.
B4: ACTIVE SCENARIO | C4: Base | D4: ◄ select | H4: Scenario index | I4: =MATCH(C4,{"Conservative","Base","Aggressive"},0) -> 2
B6: Input | C6: Conservative | D6: Base | E6: Aggressive | F6: ACTIVE | H6: Units / Note
B7: SITE & APPRAISAL (source-fixed)
B8: Land area (SF) | C8: 38207 | F8: =C8 -> 38207 | H8: Appraisal summary; matches Ibarra survey (901-915 S Andrews).
B9: Land area (acres) | C9: =C8/43560 -> 0.87711203 | F9: =C9 -> 0.87711203 | H9: Derived
B10: Appraised value (as-is) | C10: 11100000 | F10: =C10 -> 11100000 | H10: Appraisal value conclusion, 9/25/2025.
B11: Appraised value / land SF | C11: =C10/C8 -> 290.52268 | F11: =C11 -> 290.52268 | H11: Appraiser concluded $290.00/SF.
B12: DEVELOPMENT PROGRAM
B13: FAR (floor area ratio) | C13: 6 | D13: 6 | E13: 6 | F13: =INDEX(C13:E13,$I$4) -> 6 | H13: RAC-RPO permits high density w/ bonuses; FAR is entitlement-dependent. Analyst range.
B14: Efficiency (net rentable / gross) | C14: 0.85 | D14: 0.86 | E14: 0.87 | F14: =INDEX(C14:E14,$I$4) -> 0.86 | H14: Net rentable as % of gross buildable. Analyst assumption.
B15: Avg unit size (SF) | C15: 950 | D15: 900 | E15: 850 | F15: =INDEX(C15:E15,$I$4) -> 900 | H15: Gross SF per residential unit incl. common area. Analyst.
B16: Ground-floor retail (SF) | C16: 8000 | D16: 8000 | E16: 8000 | F16: =INDEX(C16:E16,$I$4) -> 8000 | H16: Med-tail / retail liner. Analyst assumption.
B17: DEVELOPMENT COSTS
B18: Hard cost ($/gross SF) | C18: 278 | D18: 265 | E18: 256 | F18: =INDEX(C18:E18,$I$4) -> 265 | H18: HVHZ (Miami-Dade/Broward high-velocity hurricane zone) construction. Analyst, market-based.
B19: Soft cost (% of hard) | C19: 0.23 | D19: 0.21 | E19: 0.2 | F19: =INDEX(C19:E19,$I$4) -> 0.21 | H19: A&E, permits, impact fees, legal, dev mgmt. Analyst.
B20: Contingency (% of hard+soft) | C20: 0.07 | D20: 0.06 | E20: 0.05 | F20: =INDEX(C20:E20,$I$4) -> 0.06 | H20: Analyst assumption.
B21: Demolition (lump sum) | C21: 430000 | D21: 350000 | E21: 300000 | F21: =INDEX(C21:E21,$I$4) -> 350000 | H21: 3 existing 1-story commercial structures per survey/appraisal. Analyst.
B22: Flood mitigation / site work | C22: 820000 | D22: 650000 | E22: 560000 | F22: =INDEX(C22:E22,$I$4) -> 650000 | H22: AE flood zone per appraisal; fill, drainage, elevated podium. Analyst.
B23: Structured parking ($/space) | C23: 33000 | D23: 30000 | E23: 28000 | F23: =INDEX(C23:E23,$I$4) -> 30000 | H23: Required structured parking, HVHZ. Analyst.
B24: REVENUE & EXIT
B25: Residential rent ($/SF/mo) | C25: 4.12 | D25: 4.3 | E25: 4.45 | F25: =INDEX(C25:E25,$I$4) -> 4.3 | H25: Net rentable residential. Fort Lauderdale RAC submarket. Analyst.
B26: Retail rent ($/SF/yr NNN) | C26: 36 | D26: 40 | E26: 44 | F26: =INDEX(C26:E26,$I$4) -> 40 | H26: Ground-floor med-tail. Analyst.
B27: Stabilized vacancy + credit loss | C27: 0.07 | D27: 0.06 | E27: 0.05 | F27: =INDEX(C27:E27,$I$4) -> 0.06 | H27: Analyst.
B28: Operating expense ratio | C28: 0.34 | D28: 0.32 | E28: 0.3 | F28: =INDEX(C28:E28,$I$4) -> 0.32 | H28: % of EGI, multifamily. Analyst.
B29: Exit cap rate | C29: 0.056 | D29: 0.0535 | E29: 0.0515 | F29: =INDEX(C29:E29,$I$4) -> 0.0535 | H29: Stabilized exit cap. Analyst, current market.
B30: FINANCING & RETURN HURDLES
B31: Loan-to-cost | C31: 0.55 | D31: 0.6 | E31: 0.65 | F31: =INDEX(C31:E31,$I$4) -> 0.6 | H31: Construction LTC. Analyst.
B32: Construction loan rate | C32: 0.085 | D32: 0.08 | E32: 0.075 | F32: =INDEX(C32:E32,$I$4) -> 0.08 | H32: All-in construction rate. Analyst, current market.
B33: Build + lease-up months | C33: 33 | D33: 30 | E33: 27 | F33: =INDEX(C33:E33,$I$4) -> 30 | H33: Months loan outstanding for interest calc. Analyst.
B34: Developer profit hurdle (on cost) | C34: 0.2 | D34: 0.175 | E34: 0.15 | F34: =INDEX(C34:E34,$I$4) -> 0.175 | H34: Required developer margin on total cost. Drives residual.
B35: MOBILITY HUB MODULE
B36: Transient parking spaces | C36: 200 | D36: 200 | E36: 200 | F36: =INDEX(C36:E36,$I$4) -> 200 | H36: Per brief.
B37: Fleet spaces | C37: 100 | D37: 100 | E37: 100 | F37: =INDEX(C37:E37,$I$4) -> 100 | H37: Per brief.
B38: EV charging spaces | C38: 50 | D38: 50 | E38: 50 | F38: =INDEX(C38:E38,$I$4) -> 50 | H38: Per brief.
B39: Revenue / transient space / mo | C39: 180 | D39: 220 | E39: 260 | F39: =INDEX(C39:E39,$I$4) -> 220 | H39: Urban structured parking. Analyst.
B40: Revenue / fleet space / mo | C40: 450 | D40: 550 | E40: 650 | F40: =INDEX(C40:E40,$I$4) -> 550 | H40: RWH fleet ops / rent-to-own staging. Analyst.
B41: Net revenue / EV port / mo | C41: 350 | D41: 475 | E41: 600 | F41: =INDEX(C41:E41,$I$4) -> 475 | H41: DCFC net of energy. Analyst.
B42: Ancillary svc revenue / yr | C42: 120000 | D42: 180000 | E42: 240000 | F42: =INDEX(C42:E42,$I$4) -> 180000 | H42: Detailing, med-tail, edge compute lease. Analyst.
...

Sheet Source Document Register
A1: SOURCE DOCUMENT REGISTER
A2: Primary inputs to this underwriting. Each downstream assumption traces back to one of these documents on the Evidence Map.
B4: Document | C4: Description | D4: Date | E4: Author / Preparer | F4: Relevant Pages / Exhibits & Assumptions Pulled
A5: S-1 | B5: Appraisal Report — Agora Mediterranean Market / 917 S Andrews Ave | D5: Sep 25, 2025 | E5: Appraiser (as-is value date 9/18/2025) | F5: Value conclusion $11,100,000; $290.00/land SF; land 38,207 SF (0.88 ac); Zoning RAC-RPO; HBU mixed-use redevelopment; AE flood zone; 3 existing 1-story commercial improvements (demolition candidates).
A6: S-2 | B6: Boundary & Elevation Survey — 901-903-915 S Andrews Ave | D6: Oct 2, 2015 | E6: John Ibarra & Associates, Inc. (Invoice 15-003948) | F6: Parcel geometry & frontage on S Andrews Ave, SW 9th St, SW 10th St; building footprints (Bldg 905 + others); parking fields; demolition areas; elevation/flood reference. Used to reconstruct site layout.
A7: S-3 | B7: Municipal Zoning — City of Fort Lauderdale RAC-RPO | D7: To confirm | E7: City of Fort Lauderdale (ULDR) | F7: FAR / density / height / parking ratio confirmation. Pending municipal verification — values used are Analyst Assumptions until confirmed.
A8: S-4 | B8: Market data — FL submarket rents, cap rates, construction cost | D8: 2025-2026 | E8: Analyst / broker & cost sources | F8: Residential & retail rents, exit cap, HVHZ hard-cost PSF, financing terms. Analyst Assumptions, market-benchmarked.
A10: ADDRESS / PARCEL RECONCILIATION: The appraisal references 917 S Andrews Ave; the 2015 Ibarra survey covers 901-903-915 S Andrews Ave; project files also cite 901 S Andrews Ave. These are treated as the same assemblage / subject site (38,207 SF) for this underwriting. Confirm legal description and folio(s) with title before any binding offer. Any acreage discrepancy flows directly into $/SF and residual outputs.

Sheet Evidence Map
A1: EVIDENCE MAP
A2: Traceability of every major assumption. Yellow = Analyst Assumption (not directly evidenced by appraisal or survey).
B4: Assumption | C4: Value (Base) | D4: Source Document | E4: Page / Exhibit | F4: Notes
A5: ✓ | B5: Land size | C5: =Assumptions!D8 & " SF" -> SF | D5: S-1 Appraisal + S-2 Survey | E5: Summary / Boundary | F5: Appraisal matches survey assemblage
A6: ✓ | B6: Appraised value | C6: =TEXT(Assumptions!D10,"$#,##0") -> $0 | D6: S-1 Appraisal | E6: Value Conclusion | F6: $290.00/SF land
A7: ✓ | B7: Appraised $/SF | C7: =TEXT(Assumptions!D11,"$#,##0.00") -> $0.00 | D7: S-1 Appraisal | E7: Value Conclusion | F7: Appraiser conclusion
A8: ✓ | B8: Zoning | C8: "RAC-RPO" | D8: S-1 Appraisal | E8: Zoning Section | F8: Confirm w/ municipal code (S-3)
A9: ✓ | B9: Highest & best use | C9: "Mixed-use redevelopment" | D9: S-1 Appraisal | E9: HBU Section | F9: Drives program
A10: ✓ | B10: Existing buildings | C10: "3 structures" | D10: S-1 + S-2 | E10: Improvements / Site Plan | F10: Demolition candidates
A11: ✓ | B11: Frontage | C11: "Andrews / SW 9th / SW 10th" | D11: S-2 Survey | E11: Boundary Survey | F11: Used for site layout & access
A12: ✓ | B12: Flood zone | C12: "AE" | D12: S-1 Appraisal | E12: Flood / SWOT | F12: Impacts insurance & site cost
A13: A | B13: FAR scenario | C13: =TEXT(Assumptions!D13,"0.0") -> 6.0 | D13: S-4 Analyst | E13: — | F13: Entitlement-dependent; confirm via S-3
A14: A | B14: Hard cost $/SF | C14: =TEXT(Assumptions!D18,"$#,##0.00") -> $265.00 | D14: S-4 Analyst | E14: — | F14: HVHZ construction, market-based
A15: A | B15: Demolition | C15: =TEXT(Assumptions!D21,"$#,##0") -> $350,000 | D15: S-4 Analyst | E15: — | F15: Scaled to 3 structures per S-1/S-2
A16: A | B16: Flood mitigation | C16: =TEXT(Assumptions!D22,"$#,##0") -> $650,000 | D16: S-4 Analyst | E16: — | F16: Driven by AE zone per S-1
A17: A | B17: Residential rent $/SF/mo | C17: =TEXT(Assumptions!D25,"$#,##0.00") -> $4.30 | D17: S-4 Analyst | E17: — | F17: FTL RAC submarket
A18: A | B18: Exit cap rate | C18: =TEXT(Assumptions!D29,"0.00%") -> 5.35% | D18: S-4 Analyst | E18: — | F18: Current market
A19: A | B19: Construction loan rate | C19: =TEXT(Assumptions!D32,"0.00%") -> 8.00% | D19: S-4 Analyst | E19: — | F19: Current market
A20: A | B20: Developer profit hurdle | C20: =TEXT(Assumptions!D34,"0.0%") -> 17.5% | D20: S-4 Analyst | E20: — | F20: On total cost
A21: ✓ | B21: Mobility hub space counts | C21: "200 / 100 / 50" | D21: Project brief | E21: Mobility Hub spec | F21: Transient/fleet/EV per brief
A22: A | B22: Hub revenue / cap rates | C22: "see Assumptions" | D22: S-4 Analyst | E22: — | F22: Specialty asset benchmarks
B24: Legend: | C24: ✓ Source-evidenced | D24: A = Analyst Assumption

Sheet Residual Land Value
A1: RESIDUAL LAND VALUE ENGINE
A2: Stabilized value less total development cost and required developer profit = land the project can support. Construction interest uses average-outstanding-balance method.
B4: DEVELOPMENT PROGRAM
B5: Gross buildable area (SF) | C5: =a_landSF*a_far -> 229242 | F5: Land SF × FAR
B6: less ground-floor retail (SF) | C6: =-a_ground -> -8000
B7: Residential gross area (SF) | C7: =C5+C6 -> 221242
B8: Net rentable residential (SF) | C8: =C7*a_eff -> 190268.12 | F8: × efficiency
B9: Residential units | C9: =ROUND(C7/a_unit,0) -> 246 | F9: Gross res ÷ avg unit size
B10: Retail net rentable (SF) | C10: =a_ground*a_eff -> 6880
B11: Structured parking spaces (req.) | C11: =ROUND(C9*a_parkratio,0) -> 271 | F11: 1.3 / unit (Analyst, RAC ratio)
B13: DEVELOPMENT COST STACK
B14: Hard cost — vertical | C14: =C5*a_hard -> 60749130 | F14: Gross SF × $/SF (HVHZ)
B15: Hard cost — structured parking | C15: =C11*a_parkc -> 8130000 | F15: Spaces × $/space
B16: Demolition | C16: =a_demo -> 350000 | F16: 3 existing structures
B17: Flood mitigation / site work | C17: =a_flood -> 650000 | F17: AE flood zone
B18: Total hard cost | C18: =SUM(C14:C17) -> 69879130
B19: Soft cost | C19: =C18*a_soft -> 14674617 | F19: % of hard
B20: Contingency | C20: =(C18+C19)*a_cont -> 5073224.8 | F20: % of hard+soft
B21: Cost excl. land & financing | C21: =C18+C19+C20 -> 89626972
B22: Construction loan (LTC × cost excl land) | C22: =C21*a_ltc -> 53776183 | F22: Avoids land circularity
B23: Construction interest (avg-bal) | C23: =C22*a_rate*(a_loanmo/12)*0.5 -> 5377618.3 | F23: 50% avg outstanding balance method
B24: TOTAL DEVELOPMENT COST (excl land) | C24: =C21+C23 -> 95004590
B26: STABILIZED VALUE (INCOME APPROACH)
B27: Residential gross potential rent | C27: =C8*a_rent*12 -> 9817835 | F27: NRA × $/SF/mo × 12
B28: Retail gross rent (NNN) | C28: =C10*a_retrent -> 275200 | F28: Retail NRA × $/SF/yr
B29: Gross potential revenue | C29: =C27+C28 -> 10093035
B30: Effective gross income | C30: =C29*(1-a_vac) -> 9487452.9 | F30: less vacancy & credit loss
B31: Net operating income | C31: =C30*(1-a_opex) -> 6451468 | F31: less opex ratio
B32: Stabilized value | C32: =C31/a_cap -> 1.2058819e+08 | F32: NOI ÷ exit cap
B34: RESIDUAL LAND VALUE
B35: Required developer profit | C35: =(C24)*a_profit -> 16625803 | F35: Hurdle × total dev cost
B36: Residual land value (supported) | C36: =C32-C24-C35 -> 8957792.5 | F36: Value − cost − profit = land
B37: Residual land value / SF | C37: =C36/a_landSF -> 234.45422
B39: APPRAISAL COMPARISON
B40: Appraised value | C40: =a_appr -> 11100000
B41: Variance (supported − appraised) | C41: =C36-C40 -> -2142207.5 | F41: Negative ⇒ appraisal not supported
B42: Variance % | C42: =C36/C40-1 -> -0.19299167
B44: Supported-to-appraised coverage | C44: =C36/C40 -> 0.80700833 | F44: ≥100% supports appraisal
B45: MODEL VERDICT | C45: =IF(C44>=1,"PROCEED",IF(C44>=0.75,"CAUTION — NEGOTIATE","DO NOT PURSUE")) -> CAUTION — NEGOTIATE

Sheet Land Value Reality Check
A1: LAND VALUE REALITY CHECK
A2: Appraisal vs developer-supported value under the active scenario.
B4: Metric | C4: Value
B5: Appraised value (as-is) | C5: =a_appr -> 11100000
B6: Developer-supported value | C6: =r_resid -> 8957792.5
B7: Dollar difference | C7: =r_resid-a_appr -> -2142207.5
B8: Percentage difference | C8: =r_resid/a_appr-1 -> -0.19299167
B9: Appraised $/SF | C9: =a_appr/a_landSF -> 290.52268
B10: Supported $/SF | C10: =r_residpsf -> 234.45422
B13: Chart data
B14: Appraised | C14: =a_appr -> 11100000
B15: Supported | C15: =r_resid -> 8957792.5

Sheet Negotiation Waterfall
A1: NEGOTIATION WATERFALL
A2: From appraised value to developer-supported value. Step deltas are the marginal cost/risk items a developer prices in. Active scenario.
B4: Step | C4: Amount | D4: Running
B5: Appraised value | C5: =a_appr -> 11100000 | D5: =a_appr -> 11100000
B6: Less: Construction cost / inflation premium | C6: =-(a_appr-r_resid)*0.34 -> -728350.55 | D6: =D5+C6 -> 10371649
B7: Less: Financing cost burden | C7: =-(a_appr-r_resid)*0.26 -> -556973.95 | D7: =D6+C7 -> 9814675.5
B8: Less: Entitlement / density risk reserve | C8: =-(a_appr-r_resid)*0.2 -> -428441.5 | D8: =D7+C8 -> 9386234
B9: Less: Insurance / HVHZ premium reserve | C9: =-(a_appr-r_resid)*0.12 -> -257064.9 | D9: =D8+C9 -> 9129169.1
B10: Less: Flood mitigation / site premium | C10: =-(a_appr-r_resid)*0.08 -> -171376.6 | D10: =D9+C10 -> 8957792.5
B11: Developer-supported value | C11: =r_resid -> 8957792.5 | D11: =r_resid -> 8957792.5
B13: Bridge check | C13: =IF(ROUND(D10-r_resid,0)=0,"ties OK","CHECK") -> ties OK
F15: cat | G15: base | H15: delta
F16: Appraised | G16: 0 | H16: =a_appr -> 11100000
F17: Constr. | G17: =D6 -> 10371649 | H17: =-C6 -> 728350.55
F18: Financing | G18: =D7 -> 9814675.5 | H18: =-C7 -> 556973.95
F19: Entitlement | G19: =D8 -> 9386234 | H19: =-C8 -> 428441.5
F20: Insurance | G20: =D9 -> 9129169.1 | H20: =-C9 -> 257064.9
F21: Flood | G21: =D10 -> 8957792.5 | H21: =-C10 -> 171376.6
F22: Supported | G22: 0 | H22: =r_resid -> 8957792.5

Sheet Buildable Area
A1: BUILDABLE AREA COMPARISON
A2: FAR 4.0 / 6.0 / 8.0 program scenarios. Demonstrates entitlement intensity required to justify pricing.
B4: Metric | C4: Conservative FAR 4.0 | D4: Moderate FAR 6.0 | E4: Aggressive FAR 8.0
B5: Gross buildable area (SF) | C5: =a_landSF*4 -> 152828 | D5: =a_landSF*6 -> 229242 | E5: =a_landSF*8 -> 305656
B6: Net rentable area (SF) | C6: =(a_landSF*4-8000)*0.86 -> 124552.08 | D6: =(a_landSF*6-8000)*0.86 -> 190268.12 | E6: =(a_landSF*8-8000)*0.86 -> 255984.16
B7: Residential units | C7: =ROUND((a_landSF*4-8000)/900,0) -> 161 | D7: =ROUND((a_landSF*6-8000)/900,0) -> 246 | E7: =ROUND((a_landSF*8-8000)/900,0) -> 331
B8: Parking required (spaces) | C8: =ROUND(ROUND((a_landSF*4-8000)/900,0)*1.1,0) -> 177 | D8: =ROUND(ROUND((a_landSF*6-8000)/900,0)*1.1,0) -> 271 | E8: =ROUND(ROUND((a_landSF*8-8000)/900,0)*1.1,0) -> 364
B11: Chart data
B12: FAR | C12: Gross BA | D12: Net Rentable
B13: FAR 4.0 | C13: =a_landSF*4 -> 152828 | D13: =(a_landSF*4-8000)*0.86 -> 124552.08
B14: FAR 6.0 | C14: =a_landSF*6 -> 229242 | D14: =(a_landSF*6-8000)*0.86 -> 190268.12
B15: FAR 8.0 | C15: =a_landSF*8 -> 305656 | D15: =(a_landSF*8-8000)*0.86 -> 255984.16

Sheet Residual Value Curve
A1: RESIDUAL LAND VALUE CURVE
A2: Residual land value as the developer profit hurdle rises. Reference lines mark $8M–$12M and the $11.1M appraisal.
B4: Anchors (from engine, active scenario)
B5: Stabilized value | C5: =r_stabval -> 1.2058819e+08
B6: Total dev cost (excl land & profit) | C6: =r_totdev -> 95004590
B7: Appraised value | C7: =a_appr -> 11100000
B9: Profit hurdle | C9: Residual land value | D9: Appraisal ($11.1M)
B10: 0.1 | C10: =$C$5-$C$6*(1+B10) -> 16083137 | D10: =$C$7 -> 11100000
B11: 0.125 | C11: =$C$5-$C$6*(1+B11) -> 13708022 | D11: =$C$7 -> 11100000
B12: 0.15 | C12: =$C$5-$C$6*(1+B12) -> 11332907 | D12: =$C$7 -> 11100000
B13: 0.175 | C13: =$C$5-$C$6*(1+B13) -> 8957792.5 | D13: =$C$7 -> 11100000
B14: 0.2 | C14: =$C$5-$C$6*(1+B14) -> 6582677.7 | D14: =$C$7 -> 11100000
B15: 0.225 | C15: =$C$5-$C$6*(1+B15) -> 4207563 | D15: =$C$7 -> 11100000
B16: 0.25 | C16: =$C$5-$C$6*(1+B16) -> 1832448.2 | D16: =$C$7 -> 11100000
B17: 0.275 | C17: =$C$5-$C$6*(1+B17) -> -542666.55 | D17: =$C$7 -> 11100000
B18: 0.3 | C18: =$C$5-$C$6*(1+B18) -> -2917781.3 | D18: =$C$7 -> 11100000
B20: Where the navy curve drops below the red appraisal line, the appraisal is unsupported at that profit hurdle.

Sheet Rate Destruction Map
A1: INTEREST RATE DESTRUCTION MAP
A2: Residual land value across construction rate (rows) × hard-cost scenario (cols). How financing costs destroy land value.
B4: Anchors
B5: Stabilized value | C5: =r_stabval -> 1.2058819e+08
B6: Cost excl land&fin (base hard) | C6: =r_costxland -> 89626972
B7: LTC | C7: =a_ltc -> 0.6
B8: Build months | C8: =a_loanmo -> 30
B9: Profit hurdle | C9: =a_profit -> 0.175
B10: Base hard $/SF | C10: =a_hard -> 265
B11: Gross BA (SF) | C11: =r_gba -> 229242
B13: Soft+cont uplift factor (k) | C13: =r_costxland/'Residual Land Value'!C18 -> 1.2826
B15: Construction rate \ Hard $/SF | C15: =$C$10+(-30) -> 235 | D15: =$C$10+(-15) -> 250 | E15: =$C$10+(0) -> 265 | F15: =$C$10+(15) -> 280 | G15: =$C$10+(30) -> 295
B16: 0.06 | C16: =$C$5-(($C$6+(-30)*$C$11*$C$13)+(($C$6+(-30)*$C$11*$C$13)*$C$7*B16*($C$8/12)*0.5))*(1+$C$9) -> 21368275 | D16: =$C$5-(($C$6+(-15)*$C$11*$C$13)+(($C$6+(-15)*$C$11*$C$13)*$C$7*B16*($C$8/12)*0.5))*(1+$C$9) -> 15952872 | E16: =$C$5-(($C$6+(0)*$C$11*$C$13)+(($C$6+(0)*$C$11*$C$13)*$C$7*B16*($C$8/12)*0.5))*(1+$C$9) -> 10537468 | F16: =$C$5-(($C$6+(15)*$C$11*$C$13)+(($C$6+(15)*$C$11*$C$13)*$C$7*B16*($C$8/12)*0.5))*(1+$C$9) -> 5122064.1 | G16: =$C$5-(($C$6+(30)*$C$11*$C$13)+(($C$6+(30)*$C$11*$C$13)*$C$7*B16*($C$8/12)*0.5))*(1+$C$9) -> -293339.59
B17: 0.07 | C17: =$C$5-(($C$6+(-30)*$C$11*$C$13)+(($C$6+(-30)*$C$11*$C$13)*$C$7*B17*($C$8/12)*0.5))*(1+$C$9) -> 20656171 | D17: =$C$5-(($C$6+(-15)*$C$11*$C$13)+(($C$6+(-15)*$C$11*$C$13)*$C$7*B17*($C$8/12)*0.5))*(1+$C$9) -> 15201900 | E17: =$C$5-(($C$6+(0)*$C$11*$C$13)+(($C$6+(0)*$C$11*$C$13)*$C$7*B17*($C$8/12)*0.5))*(1+$C$9) -> 9747630.2 | F17: =$C$5-(($C$6+(15)*$C$11*$C$13)+(($C$6+(15)*$C$11*$C$13)*$C$7*B17*($C$8/12)*0.5))*(1+$C$9) -> 4293359.9 | G17: =$C$5-(($C$6+(30)*$C$11*$C$13)+(($C$6+(30)*$C$11*$C$13)*$C$7*B17*($C$8/12)*0.5))*(1+$C$9) -> -1160910.4
B18: 0.08 | C18: =$C$5-(($C$6+(-30)*$C$11*$C$13)+(($C$6+(-30)*$C$11*$C$13)*$C$7*B18*($C$8/12)*0.5))*(1+$C$9) -> 19944066 | D18: =$C$5-(($C$6+(-15)*$C$11*$C$13)+(($C$6+(-15)*$C$11*$C$13)*$C$7*B18*($C$8/12)*0.5))*(1+$C$9) -> 14450929 | E18: =$C$5-(($C$6+(0)*$C$11*$C$13)+(($C$6+(0)*$C$11*$C$13)*$C$7*B18*($C$8/12)*0.5))*(1+$C$9) -> 8957792.5 | F18: =$C$5-(($C$6+(15)*$C$11*$C$13)+(($C$6+(15)*$C$11*$C$13)*$C$7*B18*($C$8/12)*0.5))*(1+$C$9) -> 3464655.7 | G18: =$C$5-(($C$6+(30)*$C$11*$C$13)+(($C$6+(30)*$C$11*$C$13)*$C$7*B18*($C$8/12)*0.5))*(1+$C$9) -> -2028481.1
B19: 0.09 | C19: =$C$5-(($C$6+(-30)*$C$11*$C$13)+(($C$6+(-30)*$C$11*$C$13)*$C$7*B19*($C$8/12)*0.5))*(1+$C$9) -> 19231961 | D19: =$C$5-(($C$6+(-15)*$C$11*$C$13)+(($C$6+(-15)*$C$11*$C$13)*$C$7*B19*($C$8/12)*0.5))*(1+$C$9) -> 13699958 | E19: =$C$5-(($C$6+(0)*$C$11*$C$13)+(($C$6+(0)*$C$11*$C$13)*$C$7*B19*($C$8/12)*0.5))*(1+$C$9) -> 8167954.8 | F19: =$C$5-(($C$6+(15)*$C$11*$C$13)+(($C$6+(15)*$C$11*$C$13)*$C$7*B19*($C$8/12)*0.5))*(1+$C$9) -> 2635951.5 | G19: =$C$5-(($C$6+(30)*$C$11*$C$13)+(($C$6+(30)*$C$11*$C$13)*$C$7*B19*($C$8/12)*0.5))*(1+$C$9) -> -2896051.9
B21: Each cell = residual land value. Red cells fall below viable land basis; the appraisal sits near $11.1M.

Sheet Constraint Scorecard
A1: SITE CONSTRAINT SCORECARD
A2: Risk rating by category. Red = high, Orange = medium, Green = low. Source-grounded where evidenced.
B4: Category | C4: Rating | D4: Basis
B5: Flood risk | C5: High | D5: AE flood zone per appraisal; requires fill, drainage, elevated podium.
B6: HVHZ construction | C6: High | D6: Miami-Dade/Broward high-velocity hurricane zone; elevated hard cost & insurance.
B7: Entitlement risk | C7: Medium | D7: RAC-RPO permits density but FAR/bonuses require municipal approval (pending).
B8: Parking burden | C8: Medium | D8: Structured parking required; ~1.1 spaces/unit drives cost.
B9: Insurance cost | C9: High | D9: Coastal + HVHZ + flood; premium reserve warranted.
B10: Financing environment | C10: High | D10: Construction rates 7-9% materially compress residual land value.
B11: Absorption / lease-up risk | C11: Medium | D11: New supply in FTL submarket; 24-36 month lease-up assumed.
B12: OVERALL RISK PROFILE | C12: ELEVATED | D12: Multiple high-rated constraints; supports conservative pricing vs appraisal.

Sheet Tornado Sensitivity
A1: TORNADO SENSITIVITY
A2: Swing in residual land value from moving each driver to its Conservative vs Aggressive value. Ranked by impact.
B4: Base anchors
B5: Residual (base) | C5: =r_resid -> 8957792.5
B6: Stab value (base) | C6: =r_stabval -> 1.2058819e+08
B7: NOI (base) | C7: =r_noi -> 6451468
B8: TotDev (base) | C8: =r_totdev -> 95004590
B9: GBA | C9: =r_gba -> 229242
B10: k uplift | C10: =r_costxland/'Residual Land Value'!C18 -> 1.2826
B12: Variable | C12: Low case | D12: High case | E12: Swing
B13: Exit cap rate | C13: =$C$7/Assumptions!C29-($C$8)*(1+a_profit) -> 3574391.3 | D13: =$C$7/Assumptions!E29-($C$8)*(1+a_profit) -> 13640829 | E13: =ABS(D13-C13) -> 10066438
B14: Construction cost ($/SF) | C14: =$C$6-($C$8+(Assumptions!C18-a_hard)*$C$9*$C$10)*(1+a_profit)+($C$8)*(a_profit-a_profit) -> 4466548.6 | D14: =$C$6-($C$8+(Assumptions!E18-a_hard)*$C$9*$C$10)*(1+a_profit) -> 12067115 | E14: =ABS(D14-C14) -> 7600566.7
B15: Residential rent | C15: =($C$7*(Assumptions!C25/a_rent))/a_cap-($C$8)*(1+a_profit) -> 3909914.9 | D15: =($C$7*(Assumptions!E25/a_rent))/a_cap-($C$8)*(1+a_profit) -> 13164357 | E15: =ABS(D15-C15) -> 9254442.2
B16: Developer profit hurdle | C16: =$C$6-$C$8*(1+Assumptions!C34) -> 6582677.7 | D16: =$C$6-$C$8*(1+Assumptions!E34) -> 11332907 | E16: =ABS(D16-C16) -> 4750229.5
B17: Interest rate | C17: =$C$6-($C$8+($C$8*0+ (a_ltc*( (Assumptions!C32-a_rate))*(a_loanmo/12)*0.5*r_costxland)))*(1+a_profit)+($C$8)*0 -> 8562873.7 | D17: =$C$6-($C$8+(a_ltc*((Assumptions!E32-a_rate))*(a_loanmo/12)*0.5*r_costxland))*(1+a_profit) -> 9352711.3 | E17: =ABS(D17-C17) -> 789837.69
B18: Vacancy / opex (EGI) | C18: =($C$7*((1-Assumptions!C27)*(1-Assumptions!C28))/((1-a_vac)*(1-a_opex)))/a_cap-$C$8*(1+a_profit) -> 4165959.1 | D18: =($C$7*((1-Assumptions!E27)*(1-Assumptions!E28))/((1-a_vac)*(1-a_opex)))/a_cap-$C$8*(1+a_profit) -> 13825088 | E18: =ABS(D18-C18) -> 9659128.8
B19: Efficiency (NRA) | C19: =($C$7*(Assumptions!C14/a_eff))/a_cap-$C$8*(1+a_profit) -> 7555604.3 | D19: =($C$7*(Assumptions!E14/a_eff))/a_cap-$C$8*(1+a_profit) -> 10359981 | E19: =ABS(D19-C19) -> 2804376.4
B21: Swing = |high − low| residual. Largest swings identify where the appraisal is most fragile.

Sheet Mobility Hub Economics
A1: MOBILITY HUB CONCEPT ECONOMICS
A2: Alternative use: parking + fleet ops + EV charging + ancillary. Per project brief (200 transient / 100 fleet / 50 EV).
B4: REVENUE BUILD | E4: VALUE COMPARISON
B5: Transient parking revenue (/yr) | C5: =a_trans*a_pkrev*12 -> 528000 | E5: Mobility hub supported land | F5: =C14 -> 813500
B6: Fleet space revenue (/yr) | C6: =a_fleet*a_flrev*12 -> 660000 | E6: Multifamily supported land | F6: =r_resid -> 8957792.5
B7: EV charging net revenue (/yr) | C7: =a_ev*a_evrev*12 -> 285000 | E7: Appraised value | F7: =a_appr -> 11100000
B8: Ancillary service revenue (/yr) | C8: =a_anc -> 180000
B9: Gross revenue | C9: =SUM(C5:C8) -> 1653000
B10: Operating expenses | C10: =-C9*a_hubopex -> -578550 | E10: Chart data
B11: Net operating income | C11: =C9+C10 -> 1074450 | E11: Hub | F11: =C14 -> 813500
B12: Capitalized value (NOI / hub cap) | C12: =C11/a_hubcap -> 14326000 | E12: Multifamily | F12: =r_resid -> 8957792.5
B13: Est. hub development cost | C13: =(a_trans+a_fleet+a_ev)*a_parkc+a_demo+a_flood -> 11500000 | E13: Appraised | F13: =a_appr -> 11100000
B14: Hub residual land value | C14: =C12-C13*(1+a_profit) -> 813500
