Workbook

Sheet Summary
A1: EXECUTIVE SUMMARY — 6-STORY vs 8-STORY @ $8.0M LAND
A3: Metric | B3: 6-Story | C3: 8-Story | D3: Comment
A4: Total GBA (SF) | B4: =Program!B15 -> 210000 | C4: =Program!C15 -> 280000
A5: Office floors / RSF | B5: =Program!B6&" floors / "&TEXT(Program!B14,"#,##0")&" RSF" -> 2 floors / 59,500 RSF | C5: =Program!C6&" floors / "&TEXT(Program!C14,"#,##0")&" RSF" -> 3 floors / 89,250 RSF | D5: 2 floors (6-story) vs 3 floors (8-story)
A6: Parking spaces / ratio per 1k RSF | B6: =TEXT(Program!B18,"#,##0")&" / "&TEXT(Program!B19,"0.0") -> 340 / 5.7 | C6: =TEXT(Program!C18,"#,##0")&" / "&TEXT(Program!C19,"0.0") -> 440 / 4.9 | D6: Both exceed 4.0/1,000 institutional MOB standard
A7: Total development cost | B7: =Returns!B11 -> 71515960 | C7: =Returns!B25 -> 94974410 | D7: Incl. $8.0M land, chargers, solar, BESS, AV staging, garden
A8: Stabilized NOI | B8: =Returns!B12 -> 2738118.6 | C8: =Returns!B26 -> 3819881.5 | D8: AV staging lease EXCLUDED from base (toggle on Assumptions)
A9: Yield on cost | B9: =Returns!B13 -> 0.038286819 | C9: =Returns!B27 -> 0.040220113 | D9: Target: 150+ bps spread over 6.25% exit cap
A10: Stabilized value | B10: =Returns!B14 -> 43809898 | C10: =Returns!B28 -> 61118104 | D10: NOI / 6.25% cap
A11: Development profit | B11: =Returns!B15 -> -27706063 | C11: =Returns!B29 -> -33856306
A12: Unlevered IRR (10-yr) | B12: =Returns!B16 -> 0.012437151 | C12: =Returns!B30 -> 0.018546031 | D12: QOZ 10-yr hold; levered returns higher with 65% LTC
A13: Unlevered equity multiple | B13: =Returns!B17 -> 1.1077981 | C13: =Returns!B31 -> 1.1637364
A15: GOVERNANCE NOTE (OQ-01): This session's framing ('Andrews Mobility Nexus') follows Plan 3. The base-case revenue engine remains the
A16: healthcare-anchored program per the Project Constitution and Decision Log; AV/charging/solar/edge infrastructure is built-in optionality.
A17: Flip the AV staging lease toggle to 1 on the Assumptions tab to model a signed fleet-operator lease (adds $300K/yr NOI).
A18: All yellow cells are FORECAST/JUDGMENT-class inputs. Sensitivity: change any blue Assumptions cell; entire model recalculates.

Sheet Assumptions
A1: SOUTH ANDREWS — CONSTRUCTION & RETURNS MODEL (6-Story vs 8-Story)
A2: All blue cells are inputs. Classification: FACT / ASSUMPTION / FORECAST / JUDGMENT. Basis date: Q3 2026.
A4: Input | B4: Value | C4: Unit | D4: Class | E4: Source / Note
A6: SITE & PROGRAM
A7: Site area | B7: 38207 | C7: SF | D7: FACT | E7: Broward County parcel records; Site Analysis
A8: Typical floor plate | B8: 35000 | C8: SF | D8: ASSUMPTION | E8: Operational Study programming basis (efficient plate on 38,207 SF lot)
A9: SF per structured parking space (gross) | B9: 350 | C9: SF/space | D9: ASSUMPTION | E9: Walker Consultants typical for flat-plate w/ external speed ramp
A10: Office rentable efficiency | B10: 0.85 | C10: % | D10: ASSUMPTION | E10: Core & shell over podium, side core
A11: Cafe / food service area (L1) | B11: 4500 | C11: SF | D11: ASSUMPTION | E11: Owner directive this session
A12: AV staging / ingress-egress zone (L1) | B12: 12000 | C12: SF | D12: ASSUMPTION | E12: Owner directive: separated AV ingress/egress + secured staging
A13: L1 lobby / BOH / MEP | B13: 4500 | C13: SF | D13: ASSUMPTION | E13: Typical podium ground allocation
A14: Edge compute penthouse (roof level) | B14: 2000 | C14: SF | D14: ASSUMPTION | E14: Conditioned enclosure; tenant-funded fit-out assumed
A15: Roof staff garden area | B15: 5000 | C15: SF | D15: ASSUMPTION | E15: Owner directive
A17: ACQUISITION & TIMELINE
A18: Land acquisition (starting offer) | B18: 8000000 | C18: $ | D18: ASSUMPTION | E18: Owner directive: $8.0M opening offer. Appraisal reconciliation pending (OQ-12)
A19: Demolition & sitework | B19: 850000 | C19: $ | D19: ASSUMPTION | E19: Two-parcel assemblage, minor structures, urban logistics
A20: Construction months — 6-story | B20: 18 | C20: mo | D20: ASSUMPTION | E20: CIP post-tensioned, constrained site
A21: Construction months — 8-story | B21: 21 | C21: mo | D21: ASSUMPTION | E21: Add ~1.5 mo per added level incl. structure cycle
A23: HARD COSTS (UNIT)
A24: Garage/podium shell — CIP PT FlexPark | B24: 105 | C24: $/SF | D24: ASSUMPTION | E24: S FL Q1-2026 range $85–95 conventional; +12% convertibility premium (flat plates, 12-ft F2F, 80–100 psf) per Feasibility Study
A25: Office core & shell (over podium) | B25: 310 | C25: $/SF | D25: ASSUMPTION | E25: S FL Class A MOB-capable shell over transfer level
A26: Office TI allowance | B26: 75 | C26: $/RSF | D26: ASSUMPTION | E26: Medical-capable spec suites; market TI packages $60–90
A27: Cafe/retail TI & vanilla shell premium | B27: 150 | C27: $/SF | D27: ASSUMPTION | E27: Food service infrastructure (grease, hoods, gas/elec)
A28: EV conduit rough-in (100% of stalls) | B28: 400 | C28: $/stall | D28: ASSUMPTION | E28: Raceway+capacity during construction; 10x cheaper than retrofit (Feasibility Study: run conduit to 100%)
A29: Level 2 ports — count (initial) | B29: 32 | C29: ports | D29: ASSUMPTION | E29: Owner directive: ~40 chargers total initial
A30: Level 2 — installed cost/port | B30: 8000 | C30: $/port | D30: ASSUMPTION | E30: Networked dual-port pedestal, S FL install
A31: DC fast chargers — count (initial) | B31: 8 | C31: units | D31: ASSUMPTION | E31: 150kW class; fleet/AV-capable; expandable
A32: DCFC — installed cost/unit | B32: 130000 | C32: $/unit | D32: ASSUMPTION | E32: Incl. share of switchgear/pads; excl. utility service
A33: Utility service & switchgear upgrade | B33: 750000 | C33: $ | D33: ASSUMPTION | E33: FPL service, transformers, distribution; load study pending (Operational Study DD item)
A34: AV staging fit-out (gates, LPR, bollards, canopy) | B34: 600000 | C34: $ | D34: JUDGMENT | E34: Secured staging ground, separated ingress/egress controls
A35: Solar capacity — 6-story | B35: 300 | C35: kW-DC | D35: ASSUMPTION | E35: Rooftop + top-deck canopy, net of garden/penthouse
... A42: Roof garden construction | B42: 175000 | C42: $ | D42: JUDGMENT | E42: Hardscape, shade, planting, irrigation on 5,000 SF
A44: SOFT COSTS & FEES
A45: Soft costs (% of hard) | B45: 0.18 | C45: % | D45: ASSUMPTION | E45: A/E, permits, impact fees, legal, insurance, testing
A46: Hard cost contingency | B46: 0.075 | C46: % | D46: ASSUMPTION | E46: Design-stage contingency
A47: Developer fee (% of hard+soft) | B47: 0.04 | C47: % | D47: ASSUMPTION | E47: Institutional standard 3–5%
A48: Construction loan — LTC | B48: 0.65 | C48: % | D48: ASSUMPTION | E48: Institutional construction debt
A49: Construction loan rate | B49: 0.075 | C49: % | D49: ASSUMPTION | E49: SOFR + spread, Q3-2026 indicative
A50: Avg. balance drawn during construction | B50: 0.55 | C50: % | D50: ASSUMPTION | E50: S-curve draw approximation
A52: REVENUE
...

Sheet Program
A1: BUILDING PROGRAM & STACKING
A3: Metric | B3: 6-Story | C3: 8-Story | D3: Note
A4: Stories | B4: 6 | C4: 8 | D4: Both within RAC-RPO by-right height (110 ft); 8-story preserves headroom under limit
A5: Parking levels (L2 up) | B5: 3 | C5: 4 | D5: Flat-plate FlexPark levels; external speed ramp
A6: Office levels (top of stack) | B6: 2 | C6: 3 | D6: ANSWER TO OWNER QUESTION: 2 office floors (6-story) / 3 office floors (8-story)
A7: Floor plate (SF) | B7: =Assumptions!$B$8 -> 35000 | C7: =Assumptions!$B$8 -> 35000
A8: L1 — AV staging + ingress/egress (SF) | B8: =Assumptions!$B$12 -> 12000 | C8: =Assumptions!$B$12 -> 12000 | D8: Separated, secured, blocked-off staging ground
A9: L1 — Cafe / food service (SF) | B9: =Assumptions!$B$11 -> 4500 | C9: =Assumptions!$B$11 -> 4500 | D9: Street-facing on S Andrews Ave
A10: L1 — Lobby / BOH / MEP (SF) | B10: =Assumptions!$B$13 -> 4500 | C10: =Assumptions!$B$13 -> 4500
A11: L1 — Parking / DCFC bays (SF) | B11: =B7-B8-B9-B10 -> 14000 | C11: =C7-C8-C9-C10 -> 14000 | D11: DCFC cluster sited at grade near service entry
A12: Parking GBA above grade (SF) | B12: =B5*B7 -> 105000 | C12: =C5*C7 -> 140000 | D12: Parking levels x plate
A13: Office GBA (SF) | B13: =B6*B7 -> 70000 | C13: =C6*C7 -> 105000 | D13: Office levels x plate
A14: Office RSF | B14: =B13*Assumptions!$B$10 -> 59500 | C14: =C13*Assumptions!$B$10 -> 89250 | D14: 85% efficiency
A15: Total GBA (SF) | B15: =B7+B12+B13 -> 210000 | C15: =C7+C12+C13 -> 280000 | D15: L1 + parking + office
A16: Structured spaces (upper levels) | B16: =B12/Assumptions!$B$9 -> 300 | C16: =C12/Assumptions!$B$9 -> 400 | D16: 350 SF/space gross
A17: Ground-level spaces | B17: =B11/Assumptions!$B$9 -> 40 | C17: =C11/Assumptions!$B$9 -> 40 | D17: Within L1 parking/DCFC area
A18: Total parking spaces | B18: =B16+B17 -> 340 | C18: =C16+C17 -> 440
A19: Parking ratio (spaces / 1,000 RSF office) | B19: =B18/(B14/1000) -> 5.7142857 | C19: =C18/(C14/1000) -> 4.929972 | D19: City medical req. ~4.0/1,000; institutional MOB 4.0–5.0
A20: Initial chargers (L2 ports + DCFC) | B20: =Assumptions!$B$29+Assumptions!$B$31 -> 40 | C20: =Assumptions!$B$29+Assumptions!$B$31 -> 40 | D20: 40 initial; conduit to 100% of stalls for expansion (Waymo/Zoox/Tesla interest)

Sheet Budget
A1: DEVELOPMENT BUDGET (FORMULA-DRIVEN)
A3: Line Item | B3: 6-Story | C3: 8-Story | D3: Basis
A4: Land acquisition | B4: =Assumptions!$B$18 -> 8000000 | C4: =Assumptions!$B$18 -> 8000000 | D4: Starting offer per Owner
A5: Demolition & sitework | B5: =Assumptions!$B$19 -> 850000 | C5: =Assumptions!$B$19 -> 850000
A6: Garage/podium structure (L1 + parking levels) | B6: =(Program!B7+Program!B12)*Assumptions!$B$24 -> 14700000 | C6: =(Program!C7+Program!C12)*Assumptions!$B$24 -> 18375000 | D6: CIP PT FlexPark $/SF x (L1 + parking GBA); conduit-ready convertible frame
A7: Office core & shell | B7: =Program!B13*Assumptions!$B$25 -> 21700000 | C7: =Program!C13*Assumptions!$B$25 -> 32550000 | D7: $/SF x office GBA
A8: Office TI allowance | B8: =Program!B14*Assumptions!$B$26 -> 4462500 | C8: =Program!C14*Assumptions!$B$26 -> 6693750 | D8: $/RSF x office RSF
A9: Cafe/food service TI & shell premium | B9: =Assumptions!$B$11*Assumptions!$B$27 -> 675000 | C9: =Assumptions!$B$11*Assumptions!$B$27 -> 675000 | D9: Food-service infrastructure
A10: EV conduit rough-in — 100% of stalls | B10: =Program!B18*Assumptions!$B$28 -> 136000 | C10: =Program!C18*Assumptions!$B$28 -> 176000 | D10: $/stall x total spaces (construction-phase install)
A11: Level 2 chargers (initial) | B11: =Assumptions!$B$29*Assumptions!$B$30 -> 256000 | C11: =Assumptions!$B$29*Assumptions!$B$30 -> 256000 | D11: 32 ports
A12: DC fast chargers (initial) | B12: =Assumptions!$B$31*Assumptions!$B$32 -> 1040000 | C12: =Assumptions!$B$31*Assumptions!$B$32 -> 1040000 | D12: 8 units, 150kW class
A13: Utility service & switchgear | B13: =Assumptions!$B$33 -> 750000 | C13: =Assumptions!$B$33 -> 750000 | D13: FPL load study pending
A14: AV staging fit-out | B14: =Assumptions!$B$34 -> 600000 | C14: =Assumptions!$B$34 -> 600000 | D14: Gates, LPR, bollards, canopy, comms
A15: Solar PV (net of 30% ITC) | B15: =Assumptions!$B$35*1000*Assumptions!$B$37*(1-Assumptions!$B$38) -> 546000 | C15: =Assumptions!$B$36*1000*Assumptions!$B$37*(1-Assumptions!$B$38) -> 618800 | D15: kW x $/W x (1-ITC); rooftop + top-deck canopy
A16: Battery storage (BESS) | B16: =Assumptions!$B$39*Assumptions!$B$40 -> 312000 | C16: =Assumptions!$B$39*Assumptions!$B$40 -> 312000 | D16: 600 kWh peak-shave/demand mgmt
A17: Edge compute penthouse shell | B17: =Assumptions!$B$41 -> 450000 | C17: =Assumptions!$B$41 -> 450000 | D17: Tenant funds racks/fit-out
A18: Roof staff garden | B18: =Assumptions!$B$42 -> 175000 | C18: =Assumptions!$B$42 -> 175000 | D18: 5,000 SF amenity
A19: Hard cost subtotal (excl. land) | B19: =SUM(B5:B18) -> 46652500 | C19: =SUM(C5:C18) -> 63521550
A20: Soft costs | B20: =B19*Assumptions!$B$45 -> 8397450 | C20: =C19*Assumptions!$B$45 -> 11433879
A21: Contingency | B21: =B19*Assumptions!$B$46 -> 3498937.5 | C21: =C19*Assumptions!$B$46 -> 4764116.2
A22: Developer fee | B22: =(B19+B20)*Assumptions!$B$47 -> 2201998 | C22: =(C19+C20)*Assumptions!$B$47 -> 2998217.2
A23: Construction interest (est.) | B23: =(B4+B19+B20+B21+B22)*Assumptions!$B$48*Assumptions!$B$50*Assumptions!$B$49*(Assumptions!$B$20/12) -> 2765074.7 | C23: =(C4+C19+C20+C21+C22)*Assumptions!$B$48*Assumptions!$B$50*Assumptions!$B$49*(Assumptions!$B$21/12) -> 4256647.5 | D23: LTC x avg draw x rate x months; land drawn at close
A24: TOTAL DEVELOPMENT COST (TDC) | B24: =B4+B19+B20+B21+B22+B23 -> 71515960 | C24: =C4+C19+C20+C21+C22+C23 -> 94974410
A26: TDC per GBA SF | B26: =B24/Program!B15 -> 340.55219 | C26: =C24/Program!C15 -> 339.19432
A27: TDC per parking space (garage-only view n/a — mixed use)

Sheet Operating
A1: STABILIZED OPERATING PRO FORMA (YEAR-3 DOLLARS AT CO)
A3: Line | B3: 6-Story | C3: 8-Story | D3: Basis
A4: Medical office income (NNN) | B4: =Program!B14*Assumptions!$B$53*(1-Assumptions!$B$54) -> 1992060 | C4: =Program!C14*Assumptions!$B$53*(1-Assumptions!$B$54) -> 2988090 | D4: RSF x rent x (1 - vacancy)
A5: Cafe/retail income (NNN) | B5: =Assumptions!$B$11*Assumptions!$B$55*(1-Assumptions!$B$54) -> 175770 | C5: =Assumptions!$B$11*Assumptions!$B$55*(1-Assumptions!$B$54) -> 175770
A6: Parking income (gross) | B6: =Program!B18*Assumptions!$B$56 -> 816000 | C6: =Program!C18*Assumptions!$B$56 -> 1056000 | D6: Spaces x blended $/space/yr (monthly + daily + hospital overflow + events)
A7: EV charging net income | B7: =Assumptions!$B$58 -> 120000 | C7: =Assumptions!$B$58 -> 120000 | D7: Net of energy/network
A8: Solar energy value | B8: =Assumptions!$B$35*Assumptions!$B$59*Assumptions!$B$60 -> 56550 | C8: =Assumptions!$B$36*Assumptions!$B$59*Assumptions!$B$60 -> 64090 | D8: kW x kWh/kW-yr x $/kWh avoided
A9: Edge penthouse lease (FORECAST) | B9: =Assumptions!$B$61 -> 30000 | C9: =Assumptions!$B$61 -> 30000 | D9: Small allowance
A10: AV staging ground lease (toggle) | B10: =Assumptions!$B$63*Assumptions!$B$12*Assumptions!$B$62 -> 0 | C10: =Assumptions!$B$63*Assumptions!$B$12*Assumptions!$B$62 -> 0 | D10: OFF in base case — no signed fleet operator; Constitution §5
A11: Effective gross income (EGI) | B11: =SUM(B4:B10) -> 3190380 | C11: =SUM(C4:C10) -> 4433950
A12: Less: parking opex | B12: =-B6*Assumptions!$B$57 -> -244800 | C12: =-C6*Assumptions!$B$57 -> -316800
A13: Less: management fee | B13: =-B11*Assumptions!$B$64 -> -95711.4 | C13: =-C11*Assumptions!$B$64 -> -133018.5
A14: Less: non-recoverable opex | B14: =-(Program!B13+Assumptions!$B$11)*Assumptions!$B$65 -> -111750 | C14: =-(Program!C13+Assumptions!$B$11)*Assumptions!$B$65 -> -164250
A15: STABILIZED NOI | B15: =SUM(B11:B14) -> 2738118.6 | C15: =SUM(C11:C14) -> 3819881.5

Sheet Returns
A1: RETURNS — UNLEVERED 10-YEAR HOLD, EXIT AT CAP RATE
A2: Simplified annual convention: Yr 0 land + 40% costs, Yr 1 remaining 60%; CO end of Yr 1; lease-up Yrs 2-3; stabilized Yr 4; sale end Yr 10.
A4: SCENARIO: 6-Story
A5: Year | B5: 0 | C5: 1 | D5: 2 | E5: 3 | F5: 4 | G5: 5 | H5: 6 | I5: 7 | J5: 8 | K5: 9 | L5: 10
A6: NOI | B6: 0 | C6: 0 | D6: =Operating!B15*Assumptions!$B$72 -> 1369059.3 | E6: =Operating!B15*Assumptions!$B$73*(1+Assumptions!$B$68) -> 2525914.4 | F6: =Operating!B15*(1+Assumptions!$B$68)^(4-2) -> 2876735.9 | G6: =Operating!B15*(1+Assumptions!$B$68)^(5-2) -> 2948654.3 | H6: =Operating!B15*(1+Assumptions!$B$68)^(6-2) -> 3022370.6 | I6: =Operating!B15*(1+Assumptions!$B$68)^(7-2) -> 3097929.9 | J6: =Operating!B15*(1+Assumptions!$B$68)^(8-2) -> 3175378.1 | K6: =Operating!B15*(1+Assumptions!$B$68)^(9-2) -> 3254762.6 | L6: =Operating!B15*(1+Assumptions!$B$68)^(10-2) -> 3336131.6
A7: Development cost | B7: =-(Budget!B4 + (Budget!B24-Budget!B4)*0.4) -> -33406384 | C7: =-(Budget!B24-Budget!B4)*0.6 -> -38109576 | D7: 0 | E7: 0 | F7: 0 | G7: 0 | H7: 0 | I7: 0 | J7: 0 | K7: 0 | L7: 0
A8: Net sale proceeds (end Yr 10) | B8: 0 | C8: 0 | D8: 0 | E8: 0 | F8: 0 | G8: 0 | H8: 0 | I8: 0 | J8: 0 | K8: 0 | L8: =L6*(1+Assumptions!$B$68)/Assumptions!$B$69*(1-Assumptions!$B$70) -> 53618308
A9: Net cash flow | B9: =B6+B7+B8 -> -33406384 | C9: =C6+C7+C8 -> -38109576 | D9: =D6+D7+D8 -> 1369059.3 | E9: =E6+E7+E8 -> 2525914.4 | F9: =F6+F7+F8 -> 2876735.9 | G9: =G6+G7+G8 -> 2948654.3 | H9: =H6+H7+H8 -> 3022370.6 | I9: =I6+I7+I8 -> 3097929.9 | ... L9: =L6+L7+L8 -> 56954439
A11: Total development cost (TDC) | B11: =Budget!B24 -> 71515960
A12: Stabilized NOI | B12: =Operating!B15 -> 2738118.6
A13: Yield on cost (Development yield) | B13: =Operating!B15/Budget!B24 -> 0.038286819
A14: Stabilized value (NOI / exit cap) | B14: =Operating!B15/Assumptions!$B$69 -> 43809898
A15: Development profit (value - TDC) | B15: =B14-B11 -> -27706063
A16: Unlevered IRR (10-yr) | B16: =IRR(B9:L9) -> 0.012437151
A17: Unlevered equity multiple | B17: =SUMIF(B9:L9,">0")/-SUMIF(B9:L9,"<0") -> 1.1077981
A18: SCENARIO: 8-Story
A19: Year | B19: 0 | C19: 1 | D19: 2 | E19: 3 | F19: 4 | G19: 5 | H19: 6 | I19: 7 | J19: 8 | K19: 9 | L19: 10
A20: NOI | B20: 0 | C20: 0 | D20: =Operating!C15*Assumptions!$B$72 -> 1909940.8 | E20: =Operating!C15*Assumptions!$B$73*(1+Assumptions!$B$68) -> 3523840.7 | F20: =Operating!C15*(1+Assumptions!$B$68)^(4-2) -> 4013263 | G20: =Operating!C15*(1+Assumptions!$B$68)^(5-2) -> 4113594.6 | H20: =Operating!C15*(1+Assumptions!$B$68)^(6-2) -> 4216434.4 | I20: =Operating!C15*(1+Assumptions!$B$68)^(7-2) -> 4321845.3 | J20: =Operating!C15*(1+Assumptions!$B$68)^(8-2) -> 4429891.4 | K20: =Operating!C15*(1+Assumptions!$B$68)^(9-2) -> 4540638.7 | L20: =Operating!C15*(1+Assumptions!$B$68)^(10-2) -> 4654154.7
A21: Development cost | B21: =-(Budget!C4 + (Budget!C24-Budget!C4)*0.4) -> -42789764 | C21: =-(Budget!C24-Budget!C4)*0.6 -> -52184646 | D21: 0 | E21: 0 | F21: 0 | G21: 0 | H21: 0 | I21: 0 | J21: 0 | K21: 0 | L21: 0
A22: Net sale proceeds (end Yr 10) | B22: 0 | C22: 0 | D22: 0 | E22: 0 | F22: 0 | G22: 0 | H22: 0 | I22: 0 | J22: 0 | K22: 0 | L22: =L20*(1+Assumptions!$B$68)/Assumptions!$B$69*(1-Assumptions!$B$70) -> 74801574
A23: Net cash flow | B23: =B20+B21+B22 -> -42789764 | C23: =C20+C21+C22 -> -52184646 | D23: =D20+D21+D22 -> 1909940.8 | E23: =E20+E21+E22 -> 3523840.7 | F23: =F20+F21+F22 -> 4013263 | G23: =G20+G21+G22 -> 4113594.6 | H23: =H20+H21+H22 -> 4216434.4 | I23: =I20+I21+I22 -> 4321845.3 | ... L23: =L20+L21+L22 -> 79455729
A25: Total development cost (TDC) | B25: =Budget!C24 -> 94974410
A26: Stabilized NOI | B26: =Operating!C15 -> 3819881.5
A27: Yield on cost (Development yield) | B27: =Operating!C15/Budget!C24 -> 0.040220113
A28: Stabilized value (NOI / exit cap) | B28: =Operating!C15/Assumptions!$B$69 -> 61118104
A29: Development profit (value - TDC) | B29: =B28-B25 -> -33856306
A30: Unlevered IRR (10-yr) | B30: =IRR(B23:L23) -> 0.018546031
A31: Unlevered equity multiple | B31: =SUMIF(B23:L23,">0")/-SUMIF(B23:L23,"<0") -> 1.1637364
